<?xml version="1.0" econding="utf-8"?>

<robot name="wheel_robot">

    <material name="red">
        <color rgba="1 0 0 1"/>
    </material>
  
  	<material name="blue">
        <color rgba="0 0 1 1"/>
    </material>

    <link name="base">
        <visual>
            <geometry>
                <box size="0.02 0.02 0.02"/>
            </geometry>
            <material name="red"/>
        </visual>
        <!--<collision>
            <geometry>
                <box size="0.02 0.02 0.02"/>
            </geometry>
        </collision>-->
        <inertial>
            <mass value="1"/>
            <inertia 
                ixx="0.000066667" 
                iyy="0.000066667" 
                izz="0.000066667"
                ixy="0.0" 
                ixz="0.0" 
                iyz="0.0"/>
        </inertial>
    </link>

	<link name="rod">
        <visual>
            <geometry>
                <cylinder length="0.2" radius="0.01"/>
            </geometry>
            <origin rpy="0 0 0" xyz="0 0 0.1"/>
            <material name="blue"/>
        </visual>
        <!--<collision>
            <geometry>
                <cylinder length="0.2" radius="0.01"/>
            </geometry>
            <origin rpy="0 0 0" xyz="0 0 0.1"/>
        </collision>-->
        <inertial>
            <origin rpy="0 0 0" xyz="0 0 0.1"/>
            <mass value="0.0"/>
            <inertia 
                ixx="0.0"
                iyy="0.0"
                izz="0.0"
                ixy="0.0"
                ixz="0.0"
                iyz="0.0"/>
        </inertial>
    </link>

    <link name="wheel">
        <visual>
            <geometry>
                <box size="0.25 0.25 0.04"/>
            </geometry>
            <origin rpy="1.57079 0 0" xyz="0 0 0"/>
            <material name="red"/>
        </visual>
        <collision>
            <geometry>
                <cylinder length="0.05" radius="0.15"/>
            </geometry>
            <origin rpy="1.57079 0 0" xyz="0 0 0"/>
        </collision>
        <inertial>
            <origin rpy="1.57079 0 0" xyz="0 0 0"/>
            <mass value="0.43"/>
            <inertia 
                ixx="0.02"
                iyy="0.02"
                izz="0.00272727272"
                ixy="0.0" 
                ixz="0.0" 
                iyz="0.0"/>
        </inertial>
    </link>

    <joint name="swivel" type="continuous">
        <parent link="base"/>
        <child link="rod"/>
        <axis xyz="0 1 0"/>
        <origin rpy="0 3.1415 0" xyz="0 0 0"/>
    </joint>

	<joint name="motor" type="continuous">
        <parent link="rod"/>
        <child link="wheel"/>
        <axis xyz="0 1 0"/>
        <origin xyz="0 0 0.2"/>
    </joint>

</robot>